<?xml version="1.0" ?>
<robot name="dam-typhoon" xmlns:xacro="http://ros.org/wiki/xacro">
<!--************************ include urdf ***************************-->
  <xacro:include filename="$(find dam-drone)/xacro/color_properties.xacro"/>
  <xacro:include filename="$(find dam-drone)/xacro/gazebo.xacro"/>
  <xacro:include filename="$(find dam-drone)/xacro/rotor_motor.xacro"/>

  <xacro:arg name="robot_namespace" default="/" />
  <xacro:property name="namespace" value="" />
  <!--*****************************************************************-->
  <xacro:property name="D435_cam_rgb_px" value="0.005"/>
  <xacro:property name="D435_cam_rgb_py" value="0.018"/>
  <xacro:property name="D435_cam_rgb_pz" value="0.013"/>
  <xacro:property name="D435_cam_depth_offset" value="0.01"/>
  <!--************************ plugin configs *************************-->
  <xacro:arg name="enable_mono"             default="false" />
  <xacro:arg name="enable_depth"            default="false" />
  <xacro:arg name="enable_imu"              default="false" />
  <xacro:arg name="enable_lidar"            default="false" />
  
  <!--************************** basic plugin *************************-->
  <!-- Instantiate gps plugin. -->
  <xacro:gps_plugin_macro
    namespace="${namespace}"
    gps_noise="true">
  </xacro:gps_plugin_macro>
  <!-- Instantiate barometer plugin. -->
  <xacro:barometer_plugin_macro
    namespace="${namespace}"
    pub_rate="50"
    baro_topic="/baro">
  </xacro:barometer_plugin_macro>
  <!-- Instantiate magnetometer plugin. -->
  <xacro:magnetometer_plugin_macro
    namespace="${namespace}"
    pub_rate="100"
    noise_density="0.0004"
    random_walk="0.0000064"
    bias_correlation_time="600"
    mag_topic="/mag">
  </xacro:magnetometer_plugin_macro>
  <!--*****************************************************************-->

  <!-- Typhoon H body -->
  <link name="base_link_zero"/>

  <link name="base_link">
    <inertial>
      <origin rpy="0 0 0" xyz="0 0 0"/>
      <mass value="2.02"/>
      <inertia ixx="0.011" ixy="0" ixz="0" iyy="0.015" iyz="0" izz="0.021"/>
    </inertial>
    <collision>
      <origin rpy="0 0 0" xyz="0 0 0"/>
      <geometry>
        <mesh filename="package://dam-drone/xacro/urdf/TyphoonH480/meshes/main_body_remeshed_v3.dae" scale="0.001 0.001 0.001"/>
      </geometry>
    </collision>
    <visual>
      <origin rpy="0 0 0" xyz="0 0 0"/>
      <geometry>
        <mesh filename="package://dam-drone/xacro/urdf/TyphoonH480/meshes/main_body_remeshed_v3.dae" scale="0.001 0.001 0.001"/>
      </geometry>
      <material name="darkgrey"/>
    </visual>
  </link>

  <joint name="base_link_zero_joint" type="fixed">
    <parent link="base_link_zero"/>
    <child link="base_link"/>
    <origin rpy="0 0 0" xyz="0 0 0"/>
  </joint>

  <link name="cgo3_mount_link">
    <inertial>
      <origin rpy="0 0 0" xyz="0 0 0"/>
      <!-- place holder -->
      <mass value="0.1"/>
      <inertia ixx="0.001" ixy="0" ixz="0" iyy="0.001" iyz="0" izz="0.001"/>
    </inertial>
    <collision>
      <origin rpy="0 0 0" xyz="0 0 0"/>
      <geometry>
        <mesh filename="package://dam-drone/xacro/urdf/TyphoonH480/meshes/cgo3_mount_remeshed_v1.dae" scale="0.001 0.001 0.001"/>
      </geometry>
    </collision>
    <visual>
      <origin rpy="0 0 0" xyz="0 0 0"/>
      <geometry>
        <mesh filename="package://dam-drone/xacro/urdf/TyphoonH480/meshes/cgo3_mount_remeshed_v1.dae" scale="0.001 0.001 0.001"/>
      </geometry>
      <material name="black"/>
    </visual>
  </link>

  <joint name="cgo3_mount_joint" type="fixed">
    <parent link="base_link"/>
    <child link="cgo3_mount_link"/>
    <origin rpy="0 0 0" xyz="0 0 0"/>
    <!-- <axis xyz="0 0 1"/>
    <limit effort="100" lower="0" upper="0" velocity="-1"/
    <dynamics damping="1"/>> -->
  </joint>
  
  <link name="cgo3_vertical_arm_link">
    <inertial>
      <origin rpy="0 0 0" xyz="0 0 0"/>
      <!-- place holder -->
      <mass value="0.1"/>
      <inertia ixx="0.001" ixy="0" ixz="0" iyy="0.001" iyz="0" izz="0.001"/>
    </inertial>
    
    <collision>
      <origin rpy="0 0 0" xyz="0 0 0"/>
      <geometry>
        <mesh filename="package://dam-drone/xacro/urdf/TyphoonH480/meshes/cgo3_vertical_arm_remeshed_v1.dae" scale="0.001 0.001 0.001"/>
      </geometry>
    </collision>

    <visual>
      <origin rpy="0 0 0" xyz="0 0 0"/>
      <geometry>
        <mesh filename="package://dam-drone/xacro/urdf/TyphoonH480/meshes/cgo3_vertical_arm_remeshed_v1.dae" scale="0.001 0.001 0.001"/>
      </geometry>
      <material name="black"/>
    </visual>
  </link>

  <joint name="cgo3_vertical_arm_joint" type="fixed">
    <parent link="cgo3_mount_link"/>
    <child link="cgo3_vertical_arm_link"/>
    <origin rpy="0 0 0" xyz="0 0 0.0"/>
    <!--
    <controlIndex>6</controlIndex>
    -->
    <!-- <axis xyz="0 0 1"/>
    <limit effort="100" lower="-1e16" upper="1e16" velocity="-1"/>
    <dynamics damping="0.1"/> -->
  </joint>

  <link name="cgo3_horizontal_arm_link">
    <inertial>
      <origin rpy="0 0 0" xyz="0 0 0"/>
      <!-- place holder -->
      <mass value="0.1"/>
      <inertia ixx="0.001" ixy="0" ixz="0" iyy="0.001" iyz="0" izz="0.001"/>
    </inertial>
    <collision>
      <origin rpy="0 0 0" xyz="0 0 0"/>
      <geometry>
        <mesh filename="package://dam-drone/xacro/urdf/TyphoonH480/meshes/cgo3_horizontal_arm_remeshed_v1.dae" scale="0.001 0.001 0.001"/>
      </geometry>
    </collision>
    <visual>
      <origin rpy="0 0 0" xyz="0 0 0"/>
      <geometry>
        <mesh filename="package://dam-drone/xacro/urdf/TyphoonH480/meshes/cgo3_horizontal_arm_remeshed_v1.dae" scale="0.001 0.001 0.001"/>
      </geometry>
      <material name="black"/>
    </visual>
  </link>
  <joint name="cgo3_horizontal_arm_joint" type="fixed">
    <parent link="cgo3_vertical_arm_link"/>
    <child link="cgo3_horizontal_arm_link"/>
    <origin rpy="0 0 0" xyz="0 0 0"/>
    <!--
    <controlIndex>7</controlIndex>
    -->
    <!-- <axis xyz="-1 0 0"/>
    <limit effort="100" lower="-0.785398" upper="0.785398" velocity="-1"/>
    <dynamics damping="0.1"/> -->
  </joint>

<!-- Rotor joint and link -->
  <link name="rotor_0">
    <inertial>
      <origin xyz="0 0 0" rpy="0 0 0"/>
      <mass value="0.005"/>
      <inertia ixx="9.75e-07" ixy="0" ixz="0" iyy="0.000273104" iyz="0" izz="0.000274004"/>
    </inertial>0.
    <collision>
      <origin xyz="0 0 0" rpy="0 0 0"/>
      <geometry>
          <cylinder length="0.128" radius="0.005"/>
      </geometry>
    </collision>
    <visual>
      <origin xyz="-0.211396 -0.119762 -0.082219" rpy="0 0 0"/>
      <geometry>
          <mesh filename="package://dam-drone/xacro/urdf/TyphoonH480/meshes/prop_ccw_assembly_remeshed_v3.dae" scale="0.001 0.001 0.001"/>
      </geometry>
    <material name="blue"/>
    </visual>
  </link>

  <joint name="rotor_0_joint" type="revolute">
    <origin xyz="-0.209396 0.122762 0.082219" rpy="0 0 2.09439510239"/>
    <parent link="base_link"/>
    <child link="rotor_0"/>
    <axis xyz="0.046 0.0827 1.8977"/>
    <limit effort="10" lower="-1e+16" upper="1e+16" velocity="-1"/>
    <dynamics damping="0.005"/>
  </joint>

  <link name="rotor_1">
    <inertial>
      <origin rpy="0 0 0" xyz="0 0 0"/>
      <mass value="0.005"/>
      <inertia ixx="9.75e-07" ixy="0" ixz="0" iyy="0.000273104" iyz="0" izz="0.000274004"/>
    </inertial>
    <collision>
      <origin rpy="0 0 0" xyz="0 0 0"/>
      <geometry>
          <cylinder length="0.128" radius="0.005"/>
      </geometry>
    </collision>
    <visual>
      <origin rpy="0 0 0" xyz="0.00187896 -0.242705 -0.082216"/>
      <geometry>
          <mesh filename="package://dam-drone/xacro/urdf/TyphoonH480/meshes/prop_cw_assembly_remeshed_v3.dae" scale="0.001 0.001 0.001"/>
      </geometry>
    <material name="blue"/>
    </visual>
  </link>

  <joint name="rotor_1_joint" type="revolute">
    <origin xyz="0.211396 -0.119762 0.082219" rpy="0 0 -2.09439510239"/>
    <parent link="base_link"/>
    <child link="rotor_1"/>
    <axis xyz="0.0486 0.0811 1.8976"/>
    <limit effort="10" lower="-1e+16" upper="1e+16" velocity="-1"/>
    <dynamics damping="0.005"/>
  </joint>

  <link name="rotor_2">
    <inertial>
      <origin rpy="0 0 0" xyz="0 0 0"/>
      <mass value="0.005"/>
      <inertia ixx="9.75e-07" ixy="0" ixz="0" iyy="0.000273104" iyz="0" izz="0.000274004"/>
    </inertial>
    <collision>
      <origin rpy="0 0 0" xyz="0 0 0"/>
      <geometry>
        <cylinder length="0.128" radius="0.005"/>
      </geometry>
    </collision>
    <visual>
      <origin rpy="0 0 0" xyz="0.00187896 -0.242705 -0.0822169"/>
      <geometry>
        <mesh filename="package://dam-drone/xacro/urdf/TyphoonH480/meshes/prop_cw_assembly_remeshed_v3.dae" scale="0.001 0.001 0.001"/>
      </geometry>
    <material name="blue"/>
    </visual>
  </link>
  <joint name="rotor_2_joint" type="revolute">
    <origin xyz="-0.209396 -0.122762 0.082219" rpy="0 0 2.09439510239"/>
    <parent link="base_link"/>
    <child link="rotor_2"/>
    <axis xyz="0.0404 -0.0876 1.8976"/>
    <limit effort="10" lower="-1e+16" upper="1e+16" velocity="-1"/>
    <dynamics damping="0.005"/>
  </joint>

  <link name="rotor_3">
    <inertial>
      <origin rpy="0 0 0" xyz="0 0 0"/>
      <mass value="0.005"/>
      <inertia ixx="9.75e-07" ixy="0" ixz="0" iyy="0.000273104" iyz="0" izz="0.000274004"/>
    </inertial>
    <collision>
      <origin rpy="0 0 0" xyz="0 0 0"/>
      <geometry>
        <cylinder length="0.128" radius="0.005"/>
      </geometry>
    </collision>
    <visual>
      <origin rpy="0 0 0" xyz="-0.211396 -0.119762 -0.082219"/>
      <geometry>
        <mesh filename="package://dam-drone/xacro/urdf/TyphoonH480/meshes/prop_ccw_assembly_remeshed_v3.dae" scale="0.001 0.001 0.001"/>
      </geometry>
    <material name="blue"/>
    </visual>
  </link>
  <joint name="rotor_3_joint" type="revolute">
    <origin xyz="0.211396 0.119762 0.082219" rpy="0 0 0"/>
    <parent link="base_link"/>
    <child link="rotor_3"/>
    <axis xyz="0.0446 -0.0825 1.8977"/>
    <limit effort="10" lower="-1e+16" upper="1e+16" velocity="-1"/>
    <dynamics damping="0.005"/>
  </joint>

  <link name="rotor_4">
    <inertial>
      <origin rpy="0 0 0" xyz="0 0 0"/>
      <mass value="0.005"/>
      <inertia ixx="9.75e-07" ixy="0" ixz="0" iyy="0.000273104" iyz="0" izz="0.000274004"/>
    </inertial>
    <collision>
      <origin rpy="0 0 0" xyz="0 0 0"/>
      <geometry>
        <cylinder length="0.128" radius="0.005"/>
      </geometry>
    </collision>
    <visual>
      <origin rpy="0 0 0" xyz="0.00187896 -0.242705 -0.0822169"/>
      <geometry>
        <mesh filename="package://dam-drone/xacro/urdf/TyphoonH480/meshes/prop_cw_assembly_remeshed_v3.dae" scale="0.001 0.001 0.001"/>
      </geometry>
    <material name="blue"/>
    </visual>
  </link>

  <joint name="rotor_4_joint" type="revolute">
    <origin xyz="-0.00187896 0.242705 0.0822169" rpy="0 0 0"/>
    <parent link="base_link"/>
    <child link="rotor_4"/>
    <axis xyz="-0.09563 -0.0003 1.8976"/>
    <limit effort="10" lower="-1e+16" upper="1e+16" velocity="-1"/>
    <dynamics damping="0.005"/>
  </joint>

  <link name="rotor_5">
    <inertial>
      <origin rpy="0 0 0" xyz="0 0 0"/>
      <mass value="0.005"/>
      <inertia ixx="9.75e-07" ixy="0" ixz="0" iyy="0.000273104" iyz="0" izz="0.000274004"/>
    </inertial>
    <collision>
      <origin rpy="0 0 0" xyz="0 0 0"/>
      <geometry>
        <cylinder length="0.128" radius="0.005"/>
      </geometry>
    </collision>
    <visual>
      <origin rpy="0 0 0" xyz="-0.211396 -0.119762 -0.082219"/>
      <geometry>
        <mesh filename="package://dam-drone/xacro/urdf/TyphoonH480/meshes/prop_ccw_assembly_remeshed_v3.dae" scale="0.001 0.001 0.001"/>
      </geometry>
    <material name="blue"/>
    </visual>
  </link>

  <joint name="rotor_5_joint" type="revolute">
    <origin xyz="-0.00187896 -0.242705 0.0822169" rpy="0 0 -2.09439510239"/>
    <parent link="base_link"/>
    <child link="rotor_5"/>
    <axis xyz="-0.033996 -0.0006 0.68216"/>
    <limit effort="10" lower="-1e+16" upper="1e+16" velocity="-1"/>
    <dynamics damping="0.005"/>
  </joint>

  <!-- IMU Sensor -->
  <xacro:if value="$(arg enable_imu)">
    <xacro:imu_plugin_macro
      frame_rate="1000.0"
      imu_visual="true">
    </xacro:imu_plugin_macro>
  </xacro:if>

  <!-- Camera Sensor -->
  <xacro:if value="$(arg enable_mono)">
    <xacro:camera_plugin_macro
      parent_link="cgo3_horizontal_arm_link"
      frame_rate="30.0"
      horizontal_fov="0.6"
      image_width="256"
      image_height="256"
      min_distance="0.1"
      max_distance="100"
      camera_visual="true">
    </xacro:camera_plugin_macro>
  </xacro:if>

  <!-- Depth Sensor -->
  <xacro:if value="$(arg enable_depth)">
    <xacro:depth_plugin_macro
      frame_rate="60"
      horizontal_fov="1.3439"
      image_width="1280"
      image_height="720"
      min_distance="0.05"
      max_distance="10.0">
    </xacro:depth_plugin_macro>
  </xacro:if>

  <!-- 3D Lidar Sensor -->
  <xacro:if value="$(arg enable_lidar)">
    <xacro:lidar_plugin_macro
      frame_rate="30.0"
      noise="0.008"
      h_num_ray="1875"
      v_num_ray="16"
      h_min_angle="-3.14159"
      h_max_angle="3.1415"
      v_min_angle="-0.261799"
      v_max_angle="0.26179"
      collision_range="0.055"
      min_distance="10.9"
      max_distance="130"
      lidar_visual="false">
    </xacro:lidar_plugin_macro>
  </xacro:if>

  <xacro:ardu_mavlink_interface_macro
    namespace="${namespace}"
    imu_suffix="">
  </xacro:ardu_mavlink_interface_macro> 

</robot>
